Workbook

Sheet Jan
A1: UNIT NO | B1: TYPE | C1: TENANT NAME | D1: RENT RECD | E1: RENT PER | F1: COLLECTION IN | G1: INCOME | H1: OUTSTANDING
D2: UPTO | E2: MONTH | F2: JAN'25 | G2: FOR JAN'25 | H2: AS ON 31/01/2025
A3: 1323 - AL FALAJ
A5: 01 | B5: 2BR | C5: VIMAL KUMAR | D5: 31.12.2024 | E5: 210 | F5: 210 | G5: 210 | H5: =E5 -> 210
A6: 02 | B6: 2BR | C6: PRAKASH ANANTHARAMAN SUNDARAM | D6: 31.01.2025 | E6: 200 | F6: 200 | G6: 200 | H6: 0
A7: 03 | B7: 2BR | C7: MARK ONE GENERAL TRADG LLC | D7: 30.11.2024 | E7: 210 | F7: 0 | G7: 210 | H7: =E7*2 -> 420
A8: 11 | B8: 2BR | C8: VINOD BHASKARAN | D8: 24.02.2025 | E8: 210 | F8: 210 | G8: 210 | H8: 0
A9: 12 | B9: 2BR | C9: PRASHANT PRABHAKARAN | D9: 31.01.2025 | E9: 210 | F9: 210 | G9: 210 | H9: 0
A10: 13 | B10: 2BR | C10: KRISHNAKUMAR SANTHOSHKUMAR | D10: 31.01.2025 | E10: 210 | F10: 210 | G10: 210 | H10: 0
A11: 21 | B11: 1BR | C11: VIMAL JAYAN | D11: 04.01.2025 | E11: 150 | F11: 150 | G11: 150 | H11: =E11/30*26 -> 130
A12: 22 | B12: 1BR | C12: VACANT | F12: 0 | H12: =E12*6 -> 0
A13: 23 | B13: 2BR | C13: SAMANT HEMANT YASHWANT | D13: 31.01.2025 | E13: 210 | F13: 0 | G13: 210 | H13: 0
C15: TOTAL COLLECTION | E15: =SUM(E5:E14) -> 1610 | F15: =SUM(F5:F14) -> 1190 | G15: =SUM(G5:G14) -> 1610 | H15: =SUM(H5:H14) -> 760
A16: Old Outstanding
A17: 22 | B17: 1BR | C17: SHAROON ABDUL AL SALAM | D17: 30/06/2024 | E17: 150 | F17: 0 | G17: 0 | H17: =E17*6 -> 900
H19: =SUM(H15:H18) -> 1660

Sheet Feb
A1: UNIT NO | B1: TYPE | C1: TENANT NAME | D1: RENT RECD | E1: RENT PER | F1: COLLECTION IN | G1: INCOME | H1: OUTSTANDING
D2: UPTO | E2: MONTH | F2: FEB'25 | G2: FOR MAR'25 | H2: AS ON 28.02.2025
A3: 1323 - AL FALAJ
A5: 01 | B5: 2BR | C5: VIMAL KUMAR | D5: 31.01.2025 | E5: 210 | F5: 210 | G5: 210 | H5: =E5 -> 210
A6: 02 | B6: 2BR | C6: PRAKASH ANANTHARAMAN SUNDARAM | D6: 28.02.2025 | E6: 200 | F6: 200 | G6: 200 | H6: 0
A7: 03 | B7: 2BR | C7: MARK ONE GENERAL TRADG LLC | D7: 31.01.2025 | E7: 210 | F7: 420 | G7: 210 | H7: =E7 -> 210
A8: 11 | B8: 2BR | C8: VINOD BHASKARAN | D8: 24.02.2025 | E8: 210 | F8: 0 | G8: 210 | H8: =E8/30*6 -> 42
A9: 12 | B9: 2BR | C9: PRASHANT PRABHAKARAN | D9: 31.01.2025 | E9: 210 | F9: 0 | G9: 210 | H9: =E9 -> 210
A10: 13 | B10: 2BR | C10: KRISHNAKUMAR SANTHOSHKUMAR | D10: 28.02.2025 | E10: 210 | F10: 210 | G10: 210 | H10: 0
A11: 21 | B11: 1BR | C11: VIMAL JAYAN | D11: 04.01.2025 | E11: 150 | F11: 0 | G11: 150 | H11: =E11/30*26+E11 -> 280
A12: 22 | B12: 1BR | C12: VACANT | F12: 0 | H12: =E12*6 -> 0
A13: 23 | B13: 2BR | C13: SAMANT HEMANT YASHWANT | D13: 28.02.2025 | E13: 210 | F13: 210 | G13: 210 | H13: 0
C15: TOTAL COLLECTION | E15: =SUM(E5:E14) -> 1610 | F15: =SUM(F5:F14) -> 1250 | G15: =SUM(G5:G14) -> 1610 | H15: =SUM(H5:H14) -> 952
A16: Old Outstanding
A17: 22 | B17: 1BR | C17: SHAROON ABDUL AL SALAM | D17: 30/06/2024 | E17: 150 | F17: 0 | G17: 0 | H17: =E17*6 -> 900
H19: =SUM(H15:H18) -> 1852

Sheet Mar
A1: UNIT NO | B1: TYPE | C1: TENANT NAME | D1: RENT RECD | E1: RENT PER | F1: COLLECTION IN | G1: INCOME | H1: OUTSTANDING
D2: UPTO | E2: MONTH | F2: MAR'25 | G2: FOR MAR'25 | H2: AS ON 31.03.2025
A3: 1323 - AL FALAJ
A5: 01 | B5: 2BR | C5: VIMAL KUMAR | D5: 28.02.2025 | E5: 210 | F5: 210 | G5: 210 | H5: =E5 -> 210
A6: 02 | B6: 2BR | C6: PRAKASH ANANTHARAMAN SUNDARAM | D6: 31.03.2025 | E6: 200 | F6: 200 | G6: 200 | H6: 0
A7: 03 | B7: 2BR | C7: MARK ONE GENERAL TRADG LLC | D7: 31.01.2025 | E7: 210 | F7: 0 | G7: 210 | H7: =E7*2 -> 420
A8: 11 | B8: 2BR | C8: VINOD BHASKARAN | D8: 24.03.2025 | E8: 210 | F8: 210 | G8: 210 | H8: =E8/30*6 -> 42
A9: 12 | B9: 2BR | C9: PRASHANT PRABHAKARAN | D9: 31.03.2025 | E9: 210 | F9: 420 | G9: 210 | H9: 0
A10: 13 | B10: 2BR | C10: KRISHNAKUMAR SANTHOSHKUMAR | D10: 31.03.2025 | E10: 210 | F10: 210 | G10: 210 | H10: 0
A11: 21 | B11: 1BR | C11: VIMAL JAYAN | D11: 04.02.2025 | E11: 150 | F11: 150 | G11: 150 | H11: =E11/30*26+E11 -> 280
A12: 22 | B12: 1BR | C12: VACANT | F12: 0 | H12: =E12*6 -> 0
A13: 23 | B13: 2BR | C13: SAMANT HEMANT YASHWANT | D13: 30.04.2025 | E13: 210 | F13: 420 | G13: 210 | H13: 0
C15: TOTAL COLLECTION | E15: =SUM(E5:E14) -> 1610 | F15: =SUM(F5:F14) -> 1820 | G15: =SUM(G5:G14) -> 1610 | H15: =SUM(H5:H14) -> 952
A16: Old Outstanding
A17: 22 | B17: 1BR | C17: SHAROON ABDUL AL SALAM | D17: 30/06/2024 | E17: 150 | F17: 0 | G17: 0 | H17: =E17*6 -> 900
H19: =SUM(H15:H18) -> 1852

Sheet Apr
A1: UNIT NO | B1: TYPE | C1: TENANT NAME | D1: RENT RECD | E1: RENT PER | F1: COLLECTION IN | G1: INCOME | H1: OUTSTANDING
D2: UPTO | E2: MONTH | F2: APR'25 | G2: FOR APR'25 | H2: AS ON 30/04/2025
A3: 1323 - AL FALAJ
A5: 01 | B5: 2BR | C5: VIMAL KUMAR | D5: 31.03.2025 | E5: 210 | F5: 210 | G5: 210 | H5: =E5 -> 210
A6: 02 | B6: 2BR | C6: PRAKASH ANANTHARAMAN SUNDARAM | D6: 30.04.2025 | E6: 200 | F6: 200 | G6: 200 | H6: 0
A7: 03 | B7: 2BR | C7: MARK ONE GENERAL TRADG LLC | D7: 31.03.2025 | E7: 210 | F7: 420 | G7: 210 | H7: =E7*1 -> 210
A8: 11 | B8: 2BR | C8: VINOD BHASKARAN | D8: 24.05.2025 | E8: 210 | F8: 420 | G8: 210 | H8: 0
A9: 12 | B9: 2BR | C9: PRASHANT PRABHAKARAN | D9: 30.04.2025 | E9: 210 | F9: 210 | G9: 210 | H9: 0
A10: 13 | B10: 2BR | C10: KRISHNAKUMAR SANTHOSHKUMAR | D10: 30.04.2025 | E10: 210 | F10: 210 | G10: 210 | H10: 0
A11: 21 | B11: 1BR | C11: VIMAL JAYAN | D11: 04.03.2025 | E11: 150 | F11: 150 | G11: 150 | H11: =E11/30*26+E11 -> 280
A12: 22 | B12: 1BR | C12: VACANT | F12: 0 | H12: =E12*6 -> 0
A13: 23 | B13: 2BR | C13: SAMANT HEMANT YASHWANT | D13: 31.05.2025 | E13: 210 | F13: 210 | G13: 210 | H13: 0
C15: TOTAL COLLECTION | E15: =SUM(E5:E14) -> 1610 | F15: =SUM(F5:F14) -> 2030 | G15: =SUM(G5:G14) -> 1610 | H15: =SUM(H5:H14) -> 700
A16: Old Outstanding
A17: 22 | B17: 1BR | C17: SHAROON ABDUL AL SALAM | D17: 31.07.2024 | E17: 150 | F17: 150 | G17: 0 | H17: =E17*6-150 -> 750
C19: TOTAL | F19: =SUM(F15:F18) -> 2180 | H19: =SUM(H15:H18) -> 1450

Sheet May
A1: UNIT NO | B1: TYPE | C1: TENANT NAME | D1: RENT RECD | E1: RENT PER | F1: COLLECTION IN | G1: INCOME | H1: OUTSTANDING
D2: UPTO | E2: MONTH | F2: MAY'25 | G2: FOR MAY'25 | H2: AS ON 31/05/2025
A3: 1323 - AL FALAJ
A5: 01 | B5: 2BR | C5: VIMAL KUMAR | D5: 31.05.2025 | E5: 210 | F5: 420 | G5: 210 | H5: 0
A6: 02 | B6: 2BR | C6: PRAKASH ANANTHARAMAN SUNDARAM | D6: 31.05.2025 | E6: 200 | F6: 200 | G6: 200 | H6: 0
A7: 03 | B7: 2BR | C7: MARK ONE GENERAL TRADG LLC | D7: 30.04.2025 | E7: 210 | F7: 210 | G7: 210 | H7: =E7*1 -> 210
A8: 11 | B8: 2BR | C8: VINOD BHASKARAN | D8: 24.05.2025 | E8: 210 | F8: 0 | G8: 210 | H8: =E8/30*6 -> 42
A9: 12 | B9: 2BR | C9: PRASHANT PRABHAKARAN | D9: 31.05.2025 | E9: 210 | F9: 210 | G9: 210 | H9: 0
A10: 13 | B10: 2BR | C10: KRISHNAKUMAR SANTHOSHKUMAR | D10: 31.05.2025 | E10: 210 | F10: 210 | G10: 210 | H10: 0
A11: 21 | B11: 1BR | C11: VIMAL JAYAN | D11: 04.04.2025 | E11: 150 | F11: 150 | G11: 150 | H11: =E11/30*26+E11 -> 280
A12: 22 | B12: 1BR | C12: VACANT | F12: 0 | H12: =E12*6 -> 0
A13: 23 | B13: 2BR | C13: SAMANT HEMANT YASHWANT | D13: 30.06.2025 | E13: 210 | F13: 210 | G13: 210 | H13: 0
C15: TOTAL COLLECTION | E15: =SUM(E5:E14) -> 1610 | F15: =SUM(F5:F14) -> 1610 | G15: =SUM(G5:G14) -> 1610 | H15: =SUM(H5:H14) -> 532
A16: Old Outstanding
A17: 22 | B17: 1BR | C17: SHAROON ABDUL AL SALAM | D17: 31.08.2024 | E17: 150 | F17: 150 | G17: 0 | H17: =E17*6-150-150 -> 600
C19: TOTAL | F19: =SUM(F15:F18) -> 1760 | H19: =SUM(H15:H18) -> 1132

Sheet June
A1: UNIT NO | B1: TYPE | C1: TENANT NAME | D1: RENT RECD | E1: RENT PER | F1: COLLECTION IN | G1: INCOME | H1: OUTSTANDING
D2: UPTO | E2: MONTH | F2: JUNE'25 | G2: FOR JUNE'25 | H2: AS ON 30/06/2025
A3: 1323 - AL FALAJ
A5: 01 | B5: 2BR | C5: VIMAL KUMAR | D5: 31.05.2025 | E5: 210 | F5: 0 | G5: 210 | H5: =E5 -> 210
A6: 02 | B6: 2BR | C6: PRAKASH ANANTHARAMAN SUNDARAM | D6: 30.06.2025 | E6: 200 | F6: 200 | G6: 200 | H6: 0
A7: 03 | B7: 2BR | C7: MARK ONE GENERAL TRADG LLC | D7: 31.05.2025 | E7: 210 | F7: 210 | G7: 210 | H7: =E7*1 -> 210
A8: 11 | B8: 2BR | C8: VINOD BHASKARAN | D8: 24.06.2025 | E8: 210 | F8: 210 | G8: 210 | H8: =E8/30*6 -> 42
A9: 12 | B9: 2BR | C9: PRASHANT PRABHAKARAN | D9: 30.06.2025 | E9: 210 | F9: 210 | G9: 210 | H9: 0
A10: 13 | B10: 2BR | C10: KRISHNAKUMAR SANTHOSHKUMAR | D10: 31.07.2025 | E10: 210 | F10: 420 | G10: 210 | H10: 0
A11: 21 | B11: 1BR | C11: VIMAL JAYAN | D11: 04.05.2025 | E11: 150 | F11: 150 | G11: 150 | H11: =E11/30*26+E11 -> 280
A12: 22 | B12: 1BR | C12: VACANT | F12: 0 | H12: =E12*6 -> 0
A13: 23 | B13: 2BR | C13: SAMANT HEMANT YASHWANT | D13: 31.07.2025 | E13: 210 | F13: 210 | G13: 210 | H13: 0
C15: TOTAL COLLECTION | E15: =SUM(E5:E14) -> 1610 | F15: =SUM(F5:F14) -> 1610 | G15: =SUM(G5:G14) -> 1610 | H15: =SUM(H5:H14) -> 742
A16: Old Outstanding
A17: 22 | B17: 1BR | C17: SHAROON ABDUL AL SALAM | D17: 30.09.2024 | E17: 150 | F17: 150 | G17: 0 | H17: =E17*6-150-150-150 -> 450
C19: TOTAL | F19: =SUM(F15:F18) -> 1760 | H19: =SUM(H15:H18) -> 1192

Sheet July
A1: UNIT NO | B1: TYPE | C1: TENANT NAME | D1: RENT RECD | E1: RENT PER | F1: COLLECTION IN | G1: INCOME | H1: OUTSTANDING
D2: UPTO | E2: MONTH | F2: JULY'25 | G2: FOR JULY'25 | H2: AS ON 31/07/2025
A3: 1323 - AL FALAJ
A5: 01 | B5: 2BR | C5: VIMAL KUMAR | D5: 30.06.2025 | E5: 210 | F5: 0 | G5: 210 | H5: =E5 -> 210
A6: 02 | B6: 2BR | C6: PRAKASH ANANTHARAMAN SUNDARAM | D6: 31.07.2025 | E6: 200 | F6: 200 | G6: 200 | H6: 0
A7: 03 | B7: 2BR | C7: MARK ONE GENERAL TRADG LLC | D7: 30.06.2025 | E7: 210 | F7: 210 | G7: 210 | H7: =E7*1 -> 210
A8: 11 | B8: 2BR | C8: VINOD BHASKARAN | D8: 24.08.2025 | E8: 210 | F8: 420 | G8: 210 | H8: 0
A9: 12 | B9: 2BR | C9: PRASHANT PRABHAKARAN | D9: 31.07.2025 | E9: 210 | F9: 210 | G9: 210 | H9: 0
A10: 13 | B10: 2BR | C10: KRISHNAKUMAR SANTHOSHKUMAR | D10: 31.08.2025 | E10: 210 | F10: 210 | G10: 210 | H10: 0
A11: 21 | B11: 1BR | C11: VIMAL JAYAN | D11: 04.06.2025 | E11: 150 | F11: 150 | G11: 150 | H11: =E11/30*26+E11 -> 280
A12: 22 | B12: 1BR | C12: VACANT | F12: 0 | H12: =E12*6 -> 0
A13: 23 | B13: 2BR | C13: SAMANT HEMANT YASHWANT | D13: 31.07.2025 | E13: 210 | F13: 210 | G13: 210 | H13: 0
C15: TOTAL COLLECTION | E15: =SUM(E5:E14) -> 1610 | F15: =SUM(F5:F14) -> 1610 | G15: =SUM(G5:G14) -> 1610 | H15: =SUM(H5:H14) -> 700
A16: Old Outstanding
A17: 22 | B17: 1BR | C17: SHAROON ABDUL AL SALAM | D17: 30.09.2024 | E17: 150 | F17: 0 | G17: 0 | H17: =E17*6-150-150-150 -> 450
C19: TOTAL | F19: =SUM(F15:F18) -> 1610 | H19: =SUM(H15:H18) -> 1150

Sheet Aug
A1: UNIT NO | B1: TYPE | C1: TENANT NAME | D1: RENT RECD | E1: RENT PER | F1: COLLECTION IN | G1: INCOME | H1: OUTSTANDING
D2: UPTO | E2: MONTH | F2: AUG'25 | G2: FOR AUG'25 | H2: AS ON 31/08/2025
A3: 1323 - AL FALAJ
A5: 01 | B5: 2BR | C5: VIMAL KUMAR | D5: 31.08.2025 | E5: 210 | F5: 420 | G5: 210 | H5: 0
A6: 02 | B6: 2BR | C6: PRAKASH ANANTHARAMAN SUNDARAM | D6: 31.08.2025 | E6: 200 | F6: 200 | G6: 200 | H6: 0
A7: 03 | B7: 2BR | C7: MARK ONE GENERAL TRADG LLC | D7: 31.07.2025 | E7: 210 | F7: 210 | G7: 210 | H7: =E7*1 -> 210
A8: 11 | B8: 2BR | C8: VINOD BHASKARAN | D8: 24.08.2025 | E8: 210 | F8: 0 | G8: 210 | H8: =E8/30*6 -> 42
A9: 12 | B9: 2BR | C9: PRASHANT PRABHAKARAN | D9: 31.08.2025 | E9: 210 | F9: 210 | G9: 210 | H9: 0
A10: 13 | B10: 2BR | C10: KRISHNAKUMAR SANTHOSHKUMAR | D10: 31.08.2025 | E10: 210 | F10: 0 | G10: 210 | H10: 0
A11: 21 | B11: 1BR | C11: VIMAL JAYAN | D11: 04.07.2025 | E11: 150 | F11: 150 | G11: 150 | H11: =E11/30*26+E11 -> 280
A12: 22 | B12: 1BR | C12: VACANT | F12: 0 | H12: =E12*6 -> 0
A13: 23 | B13: 2BR | C13: SAMANT HEMANT YASHWANT | D13: 30.09.2025 | E13: 210 | F13: 420 | G13: 210 | H13: 0
C15: TOTAL COLLECTION | E15: =SUM(E5:E14) -> 1610 | F15: =SUM(F5:F14) -> 1610 | G15: =SUM(G5:G14) -> 1610 | H15: =SUM(H5:H14) -> 532
A16: Old Outstanding
A17: 22 | B17: 1BR | C17: SHAROON ABDUL AL SALAM | D17: 31.10.2024 | E17: 150 | F17: 150 | G17: 0 | H17: =E17*6-150-150-150-150 -> 300
C19: TOTAL | F19: =SUM(F15:F18) -> 1760 | H19: =SUM(H15:H18) -> 832

Sheet Sep
A1: UNIT NO | B1: TYPE | C1: TENANT NAME | D1: RENT RECD | E1: RENT PER | F1: COLLECTION IN | G1: INCOME | H1: OUTSTANDING
D2: UPTO | E2: MONTH | F2: SEP'25 | G2: FOR SEP'25 | H2: AS ON 30/09/2025
A3: 1323 - AL FALAJ
A5: 01 | B5: 2BR | C5: VIMAL KUMAR | D5: 31.08.2025 | E5: 210 | F5: 0 | G5: 210 | H5: =E5 -> 210
A6: 02 | B6: 2BR | C6: PRAKASH ANANTHARAMAN SUNDARAM | D6: 30.09.2025 | E6: 200 | F6: 200 | G6: 200 | H6: 0
A7: 03 | B7: 2BR | C7: MARK ONE GENERAL TRADG LLC | D7: 30.09.2025 | E7: 210 | F7: 420 | G7: 210 | H7: 0
A8: 11 | B8: 2BR | C8: VINOD BHASKARAN | D8: 24.09.2025 | E8: 210 | F8: 210 | G8: 210 | H8: =E8/30*6 -> 42
A9: 12 | B9: 2BR | C9: PRASHANT PRABHAKARAN | D9: 30.09.2025 | E9: 210 | F9: 210 | G9: 210 | H9: 0
A10: 13 | B10: 2BR | C10: KRISHNAKUMAR SANTHOSHKUMAR | D10: 31.10.2025 | E10: 210 | F10: 420 | G10: 210 | H10: 0
A11: 21 | B11: 1BR | C11: VIMAL JAYAN | D11: 04.09.2025 | E11: 150 | F11: 300 | G11: 150 | H11: =E11/30*26 -> 130
A12: 22 | B12: 1BR | C12: MOHAMMED IRSHAD GHOUSE - From 16.09.2025 | D12: 15.10.2025 | E12: 75 | F12: 150 | G12: =E12 -> 75 | H12: 0
A13: 23 | B13: 2BR | C13: SAMANT HEMANT YASHWANT | D13: 31.10.2025 | E13: 210 | F13: 210 | G13: 210 | H13: 0
C15: TOTAL COLLECTION | E15: =SUM(E5:E14) -> 1685 | F15: =SUM(F5:F14) -> 2120 | G15: =SUM(G5:G14) -> 1685 | H15: =SUM(H5:H14) -> 382
A16: Old Outstanding
A17: 22 | B17: 1BR | C17: SHAROON ABDUL AL SALAM | D17: 30.11.2024 | E17: 150 | F17: 150 | G17: 0 | H17: =E17*6-150-150-150-150-150 -> 150
C19: TOTAL | F19: =SUM(F15:F18) -> 2270 | H19: =SUM(H15:H18) -> 532

Sheet Oct
A1: UNIT NO | B1: TYPE | C1: TENANT NAME | D1: RENT RECD | E1: RENT PER | F1: COLLECTION IN | G1: INCOME | H1: OUTSTANDING
D2: UPTO | E2: MONTH | F2: OCT'25 | G2: FOR OCT'25 | H2: AS ON 31.10.2025
A3: 1323 - AL FALAJ
A5: 01 | B5: 2BR | C5: VIMAL KUMAR | D5: 31.10.2025 | E5: 210 | F5: 420 | G5: 210 | H5: 0
A6: 02 | B6: 2BR | C6: PRAKASH ANANTHARAMAN SUNDARAM | D6: 30.09.2025 | E6: 200 | F6: 0 | G6: 200 | H6: =E6 -> 200
A7: 03 | B7: 2BR | C7: MARK ONE GENERAL TRADG LLC | D7: 30.09.2025 | E7: 210 | F7: 0 | G7: 210 | H7: =E7 -> 210
A8: 11 | B8: 2BR | C8: VINOD BHASKARAN | D8: 24.10.2025 | E8: 210 | F8: 210 | G8: 210 | H8: =E8/30*6 -> 42
A9: 12 | B9: 2BR | C9: PRASHANT PRABHAKARAN | D9: 31.10.2025 | E9: 210 | F9: 210 | G9: 210 | H9: 0
A10: 13 | B10: 2BR | C10: KRISHNAKUMAR SANTHOSHKUMAR | D10: 31.10.2025 | E10: 210 | F10: 0 | G10: 210 | H10: 0
A11: 21 | B11: 1BR | C11: VIMAL JAYAN | D11: 04.09.2025 | E11: 150 | F11: 0 | G11: 150 | H11: =E11/30*26+E11 -> 280
A12: 22 | B12: 1BR | C12: MOHAMMED IRSHAD GHOUSE | D12: 15.11.2025 | E12: 150 | F12: 150 | G12: =E12 -> 150 | H12: 0
A13: 23 | B13: 2BR | C13: SAMANT HEMANT YASHWANT | D13: 30.11.2025 | E13: 210 | F13: 210 | G13: 210 | H13: 0
C15: TOTAL COLLECTION | E15: =SUM(E5:E14) -> 1760 | F15: =SUM(F5:F14) -> 1200 | G15: =SUM(G5:G14) -> 1760 | H15: =SUM(H5:H14) -> 732
A16: Old Outstanding
A17: 22 | B17: 1BR | C17: SHAROON ABDUL AL SALAM | D17: 30.11.2024 | E17: 150 | F17: 0 | G17: 0 | H17: =E17*6-150-150-150-150-150 -> 150
C19: TOTAL | F19: =SUM(F15:F18) -> 1200 | H19: =SUM(H15:H18) -> 882

Sheet Nov
A1: UNIT NO | B1: TYPE | C1: TENANT NAME | D1: RENT RECD | E1: RENT PER | F1: COLLECTION IN | G1: INCOME | H1: OUTSTANDING
D2: UPTO | E2: MONTH | F2: NOV'25 | G2: FOR NOV'25 | H2: AS ON 30.11.2025
A3: 1323 - AL FALAJ
A5: 01 | B5: 2BR | C5: VIMAL KUMAR | D5: 31.10.2025 | E5: 210 | F5: 0 | G5: 210 | H5: 0
A6: 02 | B6: 2BR | C6: PRAKASH ANANTHARAMAN SUNDARAM | D6: 30.11.2025 | E6: 200 | F6: 400 | G6: 200 | H6: 0
A7: 03 | B7: 2BR | C7: MARK ONE GENERAL TRADG LLC | D7: 31.10.2025 | E7: 210 | F7: 210 | G7: 210 | H7: =E7 -> 210
A8: 11 | B8: 2BR | C8: VINOD BHASKARAN | D8: 24.11.2025 | E8: 210 | F8: 210 | G8: 210 | H8: =E8/30*6 -> 42
A9: 12 | B9: 2BR | C9: PRASHANT PRABHAKARAN | D9: 30.11.2025 | E9: 210 | F9: 210 | G9: 210 | H9: 0
A10: 13 | B10: 2BR | C10: KRISHNAKUMAR SANTHOSHKUMAR | D10: 31.12.2025 | E10: 210 | F10: 420 | G10: 210 | H10: 0
A11: 21 | B11: 1BR | C11: VIMAL JAYAN | D11: 04.11.2025 | E11: 150 | F11: 300 | G11: 150 | H11: =E11/30*26+E11 -> 280
A12: 22 | B12: 1BR | C12: MOHAMMED IRSHAD GHOUSE | D12: 15.12.2025 | E12: 150 | F12: 150 | G12: =E12 -> 150 | H12: 0
A13: 23 | B13: 2BR | C13: SAMANT HEMANT YASHWANT | D13: 31.12.2025 | E13: 210 | F13: 210 | G13: 210 | H13: 0
C15: TOTAL COLLECTION | E15: =SUM(E5:E14) -> 1760 | F15: =SUM(F5:F14) -> 2110 | G15: =SUM(G5:G14) -> 1760 | H15: =SUM(H5:H14) -> 532
A16: Old Outstanding
A17: 22 | B17: 1BR | C17: SHAROON ABDUL AL SALAM | D17: 31.12.2024 | E17: 150 | F17: 150 | G17: 0 | H17: =E17*6-150-150-150-150-150-150 -> 0
C19: TOTAL | F19: =SUM(F15:F18) -> 2260 | H19: =SUM(H15:H18) -> 532

Sheet Dec
A1: UNIT NO | B1: TYPE | C1: TENANT NAME | D1: RENT RECD | E1: RENT PER | F1: COLLECTION IN | G1: INCOME | H1: OUTSTANDING
D2: UPTO | E2: MONTH | F2: DEC'25 | G2: FOR DEC'25 | H2: AS ON 31.12.2025
A3: 1323 - AL FALAJ
A5: 01 | B5: 2BR | C5: VIMAL KUMAR | D5: 31.12.2025 | E5: 210 | F5: 420 | G5: 210 | H5: 0
A6: 02 | B6: 2BR | C6: PRAKASH ANANTHARAMAN SUNDARAM | D6: 31.12.2025 | E6: 200 | F6: 200 | G6: 200 | H6: 0
A7: 03 | B7: 2BR | C7: MARK ONE GENERAL TRADG LLC | D7: 30.11.2025 | E7: 210 | F7: 210 | G7: 210 | H7: =E7 -> 210
A8: 11 | B8: 2BR | C8: VINOD BHASKARAN | D8: 24.12.2025 | E8: 210 | F8: 210 | G8: 210 | H8: =E8/30*6 -> 42
A9: 12 | B9: 2BR | C9: PRASHANT PRABHAKARAN | D9: 31.12.2025 | E9: 210 | F9: 210 | G9: 210 | H9: 0
A10: 13 | B10: 2BR | C10: KRISHNAKUMAR SANTHOSHKUMAR | D10: 31.01.2026 | E10: 210 | F10: 210 | G10: 210 | H10: 0
A11: 21 | B11: 1BR | C11: VIMAL JAYAN | D11: 04.12.2025 | E11: 150 | F11: 150 | G11: 150 | H11: =E11/30*26 -> 130
A12: 22 | B12: 1BR | C12: MOHAMMED IRSHAD GHOUSE | D12: 15.01.2026 | E12: 150 | F12: 150 | G12: =E12 -> 150 | H12: 0
A13: 23 | B13: 2BR | C13: SAMANT HEMANT YASHWANT | D13: 31.01.2026 | E13: 210 | F13: 210 | G13: 210 | H13: 0
C15: TOTAL COLLECTION | E15: =SUM(E5:E14) -> 1760 | F15: =SUM(F5:F14) -> 1970 | G15: =SUM(G5:G14) -> 1760 | H15: =SUM(H5:H14) -> 382

Sheet Consolidate
B1: 1323 - Al Falaj Building | C1: Property Management Monthly Report
B3: Month | C3: JAN | D3: FEB | E3: MAR | F3: APR | G3: MAY | H3: JUN | I3: JUL | J3: AUG | K3: SEPT | L3: OCT | M3: NOV | N3: DEC | O3: YTD TOTAL
B4: General Income Overview
B5: Income as per rental agreement | C5: =Jan!E15 -> 1610 | D5: =Feb!E15 -> 1610 | E5: =Mar!E15 -> 1610 | F5: =Apr!E15 -> 1610 | G5: =May!E15 -> 1610 | H5: =June!E15 -> 1610 | I5: =July!E15 -> 1610 | J5: =Aug!E15 -> 1610 | K5: =Sep!E15 -> 1685 | L5: =Oct!E15 -> 1760 | M5: =Nov!E15 -> 1760 | N5: =Dec!E15 -> 1760 | O5: =SUM(C5:N5) -> 19845 | P5: الايجار
B7: Collection | C7: =Jan!F15 -> 1190 | D7: =Feb!F15 -> 1250 | E7: =Mar!F15 -> 1820 | F7: =Apr!F19 -> 2180 | G7: =May!F19 -> 1760 | H7: =June!F19 -> 1760 | I7: =July!F15 -> 1610 | J7: =Aug!F19 -> 1760 | K7: =Sep!F19 -> 2270 | L7: =Oct!F19 -> 1200 | M7: =Nov!F19 -> 2260 | N7: =Dec!F15 -> 1970 | O7: =SUM(C7:N7) -> 21030 | P7: التحصيلات
B9: Expenses | O9: YTD TOTAL
B10: EXPENSES OVERVIEW
B11: Muncipal Tax | C11: 0 | D11: 76.6 | E11: 0 | F11: 76.6 | I11: 76.6 | J11: 192 | K11: 55 | L11: 73 | M11: 82.52 | O11: =SUM(C11:N11) -> 632.32 | P11: رسوم البلدية
B12: Management Fees | C12: 47.6 | D12: =50+10 -> 60 | E12: 72.8 | F12: =87.2+10 -> 97.2 | G12: 70.4 | H12: 70.4 | I12: =64.4+10 -> 74.4 | J12: =70.4+30 -> 100.4 | K12: =90.8+10 -> 100.8 | L12: =48+10 -> 58 | M12: =90.4+72 -> 162.4 | N12: 78.8 | O12: =SUM(C12:N12) -> 993.2 | P12: رسوم الإدارة
B13: Value Added Tax (VAT) | C13: 4.13 | D13: 5.71 | E13: 14.14 | F13: 7.11 | G13: 5.43 | H13: 4.77 | I13: 5.86 | J13: 9.73 | K13: 11.925 | L13: 6.22 | M13: 15.095 | N13: 10.215 | O13: =SUM(C13:N13) -> 100.335 | P13: ضريبة القيمة المضافة
B14: Annual Maint. Cont. - A C, FAS, Lift & Others | D14: 249.375 | J14: 249.375 | O14: =SUM(C14:N14) -> 498.75 | P14: عقود الصيانة السنوية
B15: Sewage Removal | O15: =SUM(C15:N15) -> 0 | P15: تفريغ الصرف الصحي
B16: Common Area E/Water Charges | C16: 5.41 | D16: 5.34 | E16: 4.62 | F16: 4.78 | G16: 4.18 | H16: 4.29 | I16: 4.04 | J16: 28.33 | K16: 4.53 | L16: 4.38 | M16: 4.6 | N16: 4.41 | O16: =SUM(C16:N16) -> 78.91 | P16: استهلاك الماء و الكهرباء للاماكن العامة
B17: Legal Expenses | O17: =SUM(C17:N17) -> 0 | P17: المصاريف القانونية
B18: A C, FAS, Lift, etc. Repair Charges - (a) | C18: 126 | E18: 42 | F18: 170.1 | G18: 12.6 | H18: 8.4 | J18: 33.6 | L18: 22.05 | O18: =SUM(C18:N18) -> 414.75 | P18: تصليح المكيفات، أجهزة الحريق، المصعد، الخ
B19: Electric, Plumbing, Repair & Maint - (b) | C19: =25+10 -> 35 | D19: =25+29.2 -> 54.2 | E19: =25+185 -> 210 | F19: =25+20 -> 45 | G19: =25+13.2 -> 38.2 | H19: 25 | I19: =25+17.8 -> 42.8 | J19: =25+69.2 -> 94.2 | K19: =25+112.7 -> 137.7 | L19: =25+41.4 -> 66.4 | M19: =25+114.5 -> 139.5 | N19: =25+100.5+70 -> 195.5 | O19: =SUM(C19:N19) -> 1083.5 | P19: التصليحات الكهربائية، الميكانيكية، النجارة
B20: Total Expenses | C20: =SUM(C11:C19) -> 218.14 | D20: =SUM(D11:D19) -> 451.225 | E20: =SUM(E11:E19) -> 343.56 | F20: =SUM(F11:F19) -> 400.79 | G20: =SUM(G11:G19) -> 130.81 | H20: =SUM(H11:H19) -> 112.86 | I20: =SUM(I11:I19) -> 203.7 | J20: =SUM(J11:J19) -> 707.635 | ... N20: =SUM(N11:N19) -> 288.925 | O20: =SUM(C20:N20) -> 3801.765 | P20: اجمالي المصروفات
B22: Amount Transfer to Land Lord | C22: =C7-C20 -> 971.86 | D22: =D7-D20 -> 798.775 | E22: =E7-E20 -> 1476.44 | F22: =F7-F20 -> 1779.21 | G22: =G7-G20 -> 1629.19 | H22: =H7-H20 -> 1647.14 | I22: =I7-I20 -> 1406.3 | J22: =J7-J20 -> 1052.365 | ... N22: =N7-N20 -> 1681.075 | O22: =SUM(C22:N22) -> 17228.235 | P22: صافي الدخل منذ بداية السنة (التحصيل - المصروفات)
B24: Overdues To Date | C24: =Jan!H19 -> 1660 | D24: =Feb!H19 -> 1852 | E24: =Mar!H19 -> 1852 | F24: =Apr!H19 -> 1450 | G24: =May!H19 -> 1132 | H24: =June!H19 -> 1192 | I24: =July!H19 -> 1150 | J24: =Aug!H19 -> 832 | K24: =Sep!H19 -> 532 | L24: =Oct!H19 -> 882 | M24: =Nov!H19 -> 532 | N24: =Dec!H15 -> 382 | O24: NA | P24: المستحقات منذ بداية السنة
B26: Operational Information
B28: Details | C28: JAN | D28: FEB | E28: MAR | F28: APR | G28: MAY | H28: JUN | I28: JUL | J28: AUG | K28: SEPT | L28: OCT | M28: NOV | N28: DEC | O28: YR TOTAL
B29: Occupany
B30: Total Number of Units | C30: 9 | P30: عدد الوحدات الايجارية
B31: New Leased Residential Units | C31: 0 | D31: 0 | E31: 0 | F31: 0 | G31: 0 | H31: 0 | I31: 0 | J31: 1 | O31: NA | P31: وحدة سكنية تم تأجيرها
B32: New Leased Commercial Units | C32: 0 | D32: 0 | E32: 0 | F32: 0 | G32: 0 | H32: 0 | I32: 0 | O32: NA | P32: وحدة تجارية تم تأجيرها
B34: Total Occupied Residential Units | C34: 8 | D34: 8 | E34: 8 | F34: 8 | G34: 8 | H34: 8 | I34: 8 | J34: 8 | K34: 9 | L34: 9 | M34: 9 | N34: 9 | O34: NA | P34: الوحدات السكنية المشغولة
B35: Total Occupied Commercial Units | C35: 0 | D35: 0 | E35: 0 | F35: 0 | G35: 0 | H35: 0 | I35: 0 | J35: 0 | K35: 0 | L35: 0 | M35: 0 | N35: 0 | O35: NA | P35: الوحدات التجارية المشغولة
B36: Total Occupied Units | C36: =SUM(C31:C35) -> 8 | D36: =SUM(D31:D35) -> 8 | E36: =SUM(E31:E35) -> 8 | F36: =SUM(F31:F35) -> 8 | G36: =SUM(G31:G35) -> 8 | H36: =SUM(H31:H35) -> 8 | I36: =SUM(I31:I35) -> 8 | J36: =SUM(J31:J35) -> 9 | ... N36: =SUM(N31:N35) -> 9 | P36: مجموع الوحدات المشغولة
B37: Vacant Residential Units | C37: 1 | D37: 1 | E37: 1 | F37: 1 | G37: 1 | H37: 1 | I37: 1 | J37: 0 | K37: 0 | L37: 0 | M37: 0 | N37: 0 | O37: NA | P37: الوحدات السكنية الشاغرة
B38: Vacant Commercial Units | J38: 0 | K38: 0 | L38: 0 | M38: 0 | N38: 0 | O38: NA | P38: الوحدات التجارية الشاغرة
B40: Residential Units Under Evacuation | J40: 0 | K40: 0 | L40: 0 | M40: 0 | N40: 0 | O40: NA | P40: وحدات سكنية قيد الاخلاء
B41: Commercial Units Under Evacuation | J41: 0 | K41: 0 | L41: 0 | M41: 0 | N41: 0 | O41: NA | P41: وحدات تجارية قيد الاخلاء
B42: Total Building Occupancy Level | C42: =(C36/C30) -> 0.88888889 | D42: =(D36/C30) -> 0.88888889 | E42: =(E36/C30) -> 0.88888889 | F42: =(F36/C30) -> 0.88888889 | G42: =(G36/C30) -> 0.88888889 | H42: =(H36/C30) -> 0.88888889 | I42: =(I36/C30) -> 0.88888889 | J42: =(J36/C30) -> 1 | K42: =(K36/C30) -> 1 | L42: =(L36/C30) -> 1 | M42: =(M36/C30) -> 1 | N42: =(N36/C30) -> 1 | O42: NA | P42: معدل اشغال العقار
B43: Legal
B44: Narration
B49: Defaulters
B50: Narration
B55: Notes
B56: Maintenance | P56: الصيانة
B57: Collections | P57: التحصيلات
...
